<?xml version="1.0"?>
<robot name="demo_robot">

  <link name="base_link">

    <visual>
      <geometry>
	<cylinder length="0.01" radius="0.2"/>
      </geometry>
      <origin rpy="0 0 0" xyz="0 0 0"/>
      <material name="yellow">
        <color rgba="1 1 0 1"/>
      </material>
    </visual>

    <collision>
      <geometry>
	<box size="0.2 0.2 0.01"/>
      </geometry>
      <origin rpy="0 0 0" xyz="0 0 0.06"/>
    </collision>
  </link>

  <joint name="joint_1" type="revolute">
    <parent link="base_link"/>
    <child link="first_link"/>
    <origin xyz="0 0 0.1"/>
    <axis xyz="0 0 1" />
    <limit effort="300" velocity="0.1" lower="-3.14" upper="3.14"/>
    <dynamics damping="50" friction="1"/>
  </joint>

  <link name="first_link">
    <visual>
      <geometry>
	<cylinder length="0.2" radius="0.04"/>
      </geometry>
      <origin rpy="0 0 0" xyz="0 0 0.01"/>
      <material name="red">
        <color rgba="0 0 1 1"/>
      </material>
    </visual>
    <collision>
      <geometry>
	<cylinder length="0.2" radius="0.04"/>
      </geometry>
      <origin rpy="0 0 0" xyz="0 0 -0.04"/>
    </collision>
  </link>

  <joint name="joint_2" type="revolute">
    <parent link="first_link"/>
    <child link="second_link"/>
    <origin xyz="0 -0.04 0.06"/>
    <axis xyz="0 1 0" />
    <limit effort="300" velocity="0.1" lower="-4.64" upper="-1.5"/>
    <dynamics damping="50" friction="1"/>
  </joint>

  <link name="second_link">
    <visual>
      <geometry>
	<cylinder length="0.2" radius="0.04"/>
      </geometry>
      <origin rpy="0 1.5 0" xyz="0 0 0"/>
      <material name="green">
        <color rgba="1 0 0 1"/>
      </material>
    </visual>
    <collision>
      <geometry>
	<box size="0.1 .1 .1"/>
      </geometry>
      <origin rpy="0 0 0" xyz="0 0 0.02"/>
    </collision>
  </link>


</robot>
